Workbook
Name m.a: 'Lista de composição de preço'!$G$49
Name m.o: 'Lista de composição de preço'!$G$48

Sheet MQT
B2: CO26/0034
B3: Cliente: Tiago Parada | J3: Analise financeira | P3: FI Estrutura | R3: Negociação | S3: Lucro | T3: Custo Fixo | U3: K médio
B4: Morada: Rua António José de Almeida, 3º Direito, Brandoa, 2650-381 | P4: 1.15 | R4: 1 | S4: =J30-T4 -> 227.43 | T4: =(F28*P4)-F28 -> 227.43 | U4: =H28/F28 -> 1.3
B5: Responsável: Vinícius Tomaz | P5: Margem - K
H6: MD05.00 | P6: Const. civil | Q6: Águas | R6: Gás | S6: Eletricidade | T6: AVAC | U6: SCIE
A7: ITEM | B7: DESCRIÇÃO | C7: UN | D7: QTD | E7: VALOR UNITÁRIO CUSTO | F7: VALOR TOTAL CUSTO | G7: VALOR UNITÁRIO | H7: VALOR TOTAL | J7: Rentabilidade Estimada € | K7: Rentabilidade Estimada % | M7: COMENTÁRIOS | N7: Margem Cap. | P7: 1.15 | Q7: 1.25 | R7: 1.25 | S7: 1.25 | T7: 1.25 | U7: 1.25
A8: 1 | B8: Quarto 01 - Crianças | F8: =SUM(F9:F11) -> 759.21 | H8: =SUM(H9:H11) -> 986.973 | J8: =SUM(J9:J11) -> 227.763 | N8: =$P$7*R4 -> 1.15 | W8: Quadro de áreas
A9: 1.1 | B9: Solução para tetos interiores, constituída por estrutura com perfis metálicos horizontais F530 afastados a cada 500 mm, suspensos por elementos verticais fixados ao teto, nos quais é fixada 1 camada de placas Gyptec BA13A (STANDARD). Massas, bandas para juntas e acessórios de fixação. Superfícies prontas para acabamento final de pintura ou decoração | C9: vg | D9: 1 | E9: =M.Calculo!H22 -> 382 | F9: =D9*E9 -> 382 | G9: =((E9*$P$4*$R$4)-E9)+(E9*$N$8) -> 496.6 | H9: =G9*D9 -> 496.6 | J9: =H9-F9 -> 114.6 | K9: =(H9/F9)-100% -> 0.3 | W9: Divisão | X9: Comprimento | Y9: Largura | Z9: Altura | AA9: Área | AB9: Paredes | AC9: Teto | AD9: Perímetro
A10: 1.2 | B10: Execução de esquema de pintura em teto com Tinta Robbialac 2 em 1 branco, aplicado em 2 demão. Inclui proteção de rodapé, caixilharias, guarnições de portas, utilizando fita multisuperficies, e manga plástica para pavimento | C10: vg | D10: 1 | E10: =M.Calculo!H45 -> 214.5 | F10: =D10*E10 -> 214.5 | G10: =((E10*$P$4*$R$4)-E10)+(E10*$N$8) -> 278.85 | H10: =G10*D10 -> 278.85 | J10: =H10-F10 -> 64.35 | K10: =(H10/F10)-100% -> 0.3 | W10: Quarto | X10: 4 | Y10: 3 | Z10: 2.6 | AA10: =X10*Y10 -> 12 | AB10: =((X10*Z10)+(Y10*Z10))*2 -> 36.4 | AC10: =X10*Y10 -> 12 | AD10: =(X10+Y10)*2 -> 14
A11: 1.3 | B11: Fornecimento de Sanca HOMESTAR A5 200X3.5X3.5cm em todo perimetro do teto falso. | C11: vg | D11: 1 | E11: =M.Calculo!H68 -> 162.71 | F11: =D11*E11 -> 162.71 | G11: =((E11*$P$4*$R$4)-E11)+(E11*$N$8) -> 211.523 | H11: =G11*D11 -> 211.523 | J11: =H11-F11 -> 48.813 | K11: =(H11/F11)-100% -> 0.3 | W11: Quarto 2 | X11: =2.5+3 -> 5.5 | Y11: 2.1 | Z11: 2.6 | AA11: =X11*Y11 -> 11.55 | AB11: =((X11*Z11)+(Y11*Z11))*2 -> 39.52 | AC11: =X11*Y11 -> 11.55 | AD11: =(X11+Y11)*2 -> 15.2
A12: 2 | F12: =SUM(F13:F16) -> 756.99 | H12: =SUM(H13:H16) -> 984.087 | J12: =SUM(J13:J16) -> 227.097 | N12: =$P$7*R4 -> 1.15 | AA12: =X12*Y12 -> 0 | AB12: =((X12*Z12)+(Y12*Z12))*2 -> 0 | AC12: =X12*Y12 -> 0 | AD12: =(X12+Y12)*2 -> 0
A13: 2.1 | B13: Solução para tetos interiores, constituída por estrutura com perfis metálicos horizontais F530 afastados a cada 500 mm, suspensos por elementos verticais fixados ao teto, nos quais é fixada 1 camada de placas Gyptec BA13A (STANDARD). Massas, bandas para juntas e acessórios de fixação. Superfícies prontas para acabamento final de pintura ou decoração | C13: vg | D13: 1 | E13: =M.Calculo!H91 -> 382 | F13: =D13*E13 -> 382 | G13: =((E13*$P$4*$R$4)-E13)+(E13*$N$8) -> 496.6 | H13: =G13*D13 -> 496.6 | J13: =H13-F13 -> 114.6 | K13: =(H13/F13)-100% -> 0.3 | AA13: =X13*Y13 -> 0 | AB13: =((X13*Z13)+(Y13*Z13))*2 -> 0 | AC13: =X13*Y13 -> 0 | AD13: =(X13+Y13)*2 -> 0
A14: 2.2 | B14: Execução de esquema de pintura em teto com Tinta Robbialac 2 em 1 branco, aplicado em 2 demão. Inclui proteção de rodapé, caixilharias, guarnições de portas, utilizando fita multisuperficies, e manga plástica para pavimento | C14: vg | D14: 1 | E14: =M.Calculo!H114 -> 209.5 | F14: =D14*E14 -> 209.5 | G14: =((E14*$P$4*$R$4)-E14)+(E14*$N$8) -> 272.35 | H14: =G14*D14 -> 272.35 | J14: =H14-F14 -> 62.85 | K14: =(H14/F14)-100% -> 0.3 | AA14: =X14*Y14 -> 0 | AB14: =((X14*Z14)+(Y14*Z14))*2 -> 0 | AC14: =X14*Y14 -> 0 | AD14: =(X14+Y14)*2 -> 0
A15: 2.3 | B15: Fornecimento de Sanca HOMESTAR A5 200X3.5X3.5cm em todo perimetro do teto falso. | C15: vg | D15: 1 | E15: =M.Calculo!H137 -> 165.49 | F15: =D15*E15 -> 165.49 | G15: =((E15*$P$4*$R$4)-E15)+(E15*$N$8) -> 215.137 | H15: =G15*D15 -> 215.137 | J15: =H15-F15 -> 49.647 | K15: =(H15/F15)-100% -> 0.3 | AA15: =X15*Y15 -> 0 | AB15: =((X15*Z15)+(Y15*Z15))*2 -> 0 | AC15: =X15*Y15 -> 0 | AD15: =(X15+Y15)*2 -> 0
AA16: =X16*Y16 -> 0 | AB16: =((X16*Z16)+(Y16*Z16))*2 -> 0 | AC16: =X16*Y16 -> 0 | AD16: =(X16+Y16)*2 -> 0
W17: TOTAL | AA17: =SUM(AA10:AA16) -> 23.55 | AB17: =SUM(AB10:AB16) -> 75.92 | AC17: =SUM(AC10:AC16) -> 23.55 | AD17: =SUM(AD10:AD16) -> 29.2
A20: Notas: | J20: Imposto sobre orçamento
A21: 1 - | B21: A proposta só é válida em sua globalidade, reservando a empresa o direito de rever os valores em caso de adjudicação parcial. | K21: IVA | L21: 0.23
A22: 2 - | B22: Todos os trabalhos foram considerados em horário normal. | K22: IVA | L22: 0.06
A23: 3 - | B23: Condições de pagamento: 50% na adjudicação a P.P. e, 50% nos términos dos trabalhos a P.P. *P.P. (Pronto pagamento) | J23: Total a Faturar | M23: =M22+J22 -> 0
A24: 4 - | B24: Todos os itens omissos serão apresentados em forma de proposta para avaliação do cliente. | J24: Condições de pagamento
A25: 5 - | B25: Não está considerado movimentação de móveis e/ou bens pessoais | J25: 1º Fatura | K25: 0.5 | M25: =K25*H28 -> 985.53
J26: 2º Fatura | K26: 0.5 | M26: =K26*H28 -> 985.53
F27: TOTAL CUSTO | H27: TOTAL PROPOSTA | J27: 3º Fatura | K27: 0 | M27: =K27*H28 -> 0
F28: =F17+F12+F8 -> 1516.2 | H28: =SUM(H17,H12,H8) -> 1971.06
J29: LUCRO ESTIMADO
J30: =SUM(J17,J12,J8) -> 454.86

Sheet M.Calculo
B2: ITEM | C2: DESCRIÇÃO | D2: UN | E2: QTD | G2: V.UN | H2: V.TOTAL | I2: Consumos /rendimentos | K2: Tempo em dias | L2: Vazadouro | N2: Ref. ITEM
E3: Qtd padrão | F3: Qtd pontual | I3: Valor | J3: Unidade | L3: Material | M3: Volume m3
B4: =MQT!B9 -> Solução para tetos interiores, constituída por estrutura com perfis metálicos horizontais F530 afastados a cada 500 mm, suspensos por elementos verticais fixados ao teto, nos quais é fixada 1 camada de placas Gyptec BA13A (STANDARD). Massas, bandas para juntas e acessórios de fixação. Superfícies prontas para acabamento final de pintura ou decoração | C4: Mão de obra | H4: =SUM(H5:H6) -> 216 | K4: =((E5+E6)/2)/8 -> 1
C5: M.Oficial | D5: h | E5: 8 | F5: 1 | G5: 15 | H5: =G5*E5*F5 -> 120
C6: M.Ajudante | D6: h | E6: 8 | F6: 1 | G6: 12 | H6: =G6*E6*F6 -> 96
C7: Materiais | H7: =SUM(H8:H10) -> 125
C8: Material para teto falso | D8: un | E8: 1 | F8: 1 | G8: 125 | H8: =G8*E8*F8 -> 125
H9: =G9*E9*F9 -> 0
H10: =G10*E10*F10 -> 0
C11: Aluguel | H11: =SUM(H12:H14) -> 0
C12: Martelo demolidor 6kg aluguer | D12: dia | E12: 1 | F12: 0 | G12: 25 | H12: =G12*E12*F12 -> 0
C13: Broca martelo | D13: cj | E13: 1 | F13: 0 | G13: 4 | H13: =G13*E13*F13 -> 0
C15: Vazadouro | H15: =SUM(H16:H17) -> 11 | L15: Reboco | M15: =2*5*0.02*1.1 -> 0.22
C16: Vazadouro | D16: vg | E16: =ROUNDUP((SUM(M4:M23)/300),0) -> 1 | F16: 1 | G16: 5 | H16: =G16*E16*F16 -> 5
C17: Transporte de lixo | D17: h | E17: 1 | F17: 0.5 | G17: 12 | H17: =G17*E17*F17 -> 6
C18: Transporte | H18: =SUM(H19) -> 20
C19: Transporte TKH | D19: dia | E19: 1 | F19: 1 | G19: =(20*E5)/8 -> 20 | H19: =G19*E19*F19 -> 20
C20: Extras - Diversos | H20: =SUM(H21) -> 10
C21: Acessórios | D21: vg | E21: 1 | F21: 1 | G21: 10 | H21: =G21*E21*F21 -> 10
C22: Total | H22: =SUM(H4,H7,H11,H15,H18,H20) -> 382
C23: Total/m2 | G23: =MQT!AA10 -> 12 | H23: =ROUNDUP((H22/G23),0) -> 32
B25: ITEM | C25: DESCRIÇÃO | D25: UN | E25: QTD | G25: V.UN | H25: V.TOTAL | I25: Consumos /rendimentos | K25: Tempo em dias | L25: Vazadouro | N25: Ref. ITEM
E26: Qtd padrão | F26: Qtd pontual | I26: Valor | J26: Unidade | L26: Material | M26: Volume m3
B27: =MQT!B10 -> Execução de esquema de pintura em teto com Tinta Robbialac 2 em 1 branco, aplicado em 2 demão. Inclui proteção de rodapé, caixilharias, guarnições de portas, utilizando fita multisuperficies, e manga plástica para pavimento | C27: Mão de obra | H27: =SUM(H28:H29) -> 108 | K27: =((E28+E29)/2)/8 -> 0.5
C28: M.Oficial | D28: h | E28: 4 | F28: 1 | G28: 15 | H28: =G28*E28*F28 -> 60
C29: M.Ajudante | D29: h | E29: 4 | F29: 1 | G29: 12 | H29: =G29*E29*F29 -> 48
C30: Materiais | H30: =SUM(H31:H33) -> 49.5
C31: Tinta interior parede Branco facil robbialac branco mate 15L | D31: un | E31: 1 | F31: 1 | G31: =99/2 -> 49.5 | H31: =G31*E31*F31 -> 49.5
H32: =G32*E32*F32 -> 0
H33: =G33*E33*F33 -> 0
C34: Aluguel | H34: =SUM(H35:H37) -> 0
C35: Martelo demolidor 10kg aluguer | D35: dia | E35: 1 | F35: 0 | G35: 25 | H35: =G35*E35*F35 -> 0
C36: Broca martelo | D36: cj | E36: 1 | F36: 0 | G36: 4 | H36: =G36*E36*F36 -> 0
C38: Vazadouro | H38: =SUM(H39:H40) -> 17 | L38: Reboco | M38: =2*5*0.02*1.1 -> 0.22
C39: Vazadouro | D39: vg | E39: =ROUNDUP((SUM(M27:M46)/300),0) -> 1 | F39: 1 | G39: 5 | H39: =G39*E39*F39 -> 5
C40: Transporte de lixo | D40: h | E40: 1 | F40: 1 | G40: 12 | H40: =G40*E40*F40 -> 12
C41: Transporte | H41: =SUM(H42) -> 10
C42: Transporte TKH | D42: dia | E42: 1 | F42: 1 | G42: =(20*E28)/8 -> 10 | H42: =G42*E42*F42 -> 10
C43: Extras - Diversos | H43: =SUM(H44) -> 30
C44: Acessórios | D44: vg | E44: 1 | F44: 1 | G44: 30 | H44: =G44*E44*F44 -> 30
...

Sheet Lista de composição de preço
B2: Demolição
B4: ITEM | C4: DESCRIÇÃO | D4: UN | E4: QTD | G4: V.UN | H4: V.TOTAL | I4: Consumos /rendimentos | K4: Tempo em dias | L4: Vazadouro | N4: Ref. ITEM
E5: Qtd padrão | F5: Qtd pontual | I5: Valor | J5: Unidade | L5: Material | M5: Volume
B6: Montagem e desmontagem de estaleiro provisório, incluindo a organização inicial do canteiro de obras com definição de áreas de armazenamento. Considera-se fornecimento de meios elevatórios para execução dos trabalhos, todos homolagos pelo CE e seguindo as normas de SST. | C6: M.Oficial | D6: h | E6: 4 | F6: 1 | G6: 17 | H6: =G6*E6*F6 -> 68 | K6: =((E6+E7)/2)/8 -> 0.5
C7: M.Ajudante | D7: h | E7: 4 | F7: 1 | G7: 12 | H7: =G7*E7*F7 -> 48
C8: Escada multifunções MULTIUSOS 4X3 COM PLATAFORMA 3.49M | D8: dia | E8: 10 | F8: 1 | G8: =150/365 -> 0.4109589 | H8: =G8*E8*F8 -> 4.109589
C9: Andaime - transporte | D9: un | F9: 2 | G9: 55 | H9: =G9*E9*F9 -> 0
C10: Aluguer aindame | D10: dia | F10: 1 | G10: 5.5 | H10: =G10*E10*F10 -> 0
C11: Andaime dobrável 90x190 plataforma 190 C/E - 4,70 m altura de trabalho | D11: dia | F11: 1 | G11: =1950/365 -> 5.3424658 | H11: =G11*E11*F11 -> 0 | N11: https://www.iberandamios.com/pt/andaime-dobravel-90-cm/andaime-dobravel-90x190-plataforma-190-ce-470-m-altura-de-trabalho/
C12: Vazadouro | D12: un | E12: =ROUNDUP((SUM(M6:M16)/300),0) -> 0 | G12: 200 | H12: =G12*E12*F12 -> 0
C13: Transporte TKH | D13: un | E13: 1 | F13: 1 | G13: 20 | H13: =G13*E13*F13 -> 20
C14: Acessórios | D14: vg | E14: 1 | F14: 1 | G14: 10 | H14: =G14*E14*F14 -> 10
C15: Total | H15: =SUM(H6:H14) -> 150.10959
C16: Total/m2 | E16: Área | G16: 10 | H16: =ROUNDUP((H15/G16),0) -> 16
B18: ITEM | C18: DESCRIÇÃO | D18: UN | E18: QTD | G18: V.UN | H18: V.TOTAL | I18: Consumos /rendimentos | K18: Tempo em dias | L18: Vazadouro | N18: Ref. ITEM
E19: Qtd padrão | F19: Qtd pontual | I19: Valor | J19: Unidade | L19: Material | M19: Volume
B20: Fornecimento de meios elevatórios tipo: Braço articulado 12m a Disel, incluindo carga, transporte e recolha de equipamento em obra. | C20: M.Oficial | D20: h | E20: 4 | F20: 1 | G20: 17 | H20: =G20*E20*F20 -> 68
C21: M.Ajudante | D21: h | E21: 0 | F21: 1 | G21: 12 | H21: =G21*E21*F21 -> 0
C22: Braço articulado 12 m disel - GoingUp | D22: dias | E22: 1 | F22: 1 | G22: 65 | H22: =G22*E22*F22 -> 65
C23: Entrega de equipamento | D23: un | E23: 1 | F23: 1 | G23: 150 | H23: =G23*E23*F23 -> 150
C24: Recolha de equipamento | D24: un | E24: 1 | F24: 1 | G24: 150 | H24: =G24*E24*F24 -> 150
H25: =G25*E25*F25 -> 0
H26: =G26*E26*F26 -> 0
C27: Transporte TKH | D27: un | E27: 1 | F27: 1 | G27: 20 | H27: =G27*E27*F27 -> 20
C28: Acessórios | D28: vg | E28: 1 | F28: 1 | G28: 10 | H28: =G28*E28*F28 -> 10
C29: Total | H29: =SUM(H20:H28) -> 463
C30: Total/m2 | E30: Área | G30: 10 | H30: =ROUNDUP((H29/G30),0) -> 47
B32: ITEM | C32: DESCRIÇÃO | D32: UN | E32: QTD | G32: V.UN | H32: V.TOTAL | I32: Consumos /rendimentos | K32: Tempo em dias | L32: Vazadouro | N32: Ref. ITEM
E33: Qtd padrão | F33: Qtd pontual | I33: Valor | J33: Unidade | L33: Material | M33: Volume
B34: Picagem de reboco existente paredes e/ou tetos, utilizando martelo pneumático de 8 kg. O serviço inclui carga, transporte e descarte dos materiais resultantes em vazadouro autorizado. | C34: M.Oficial | D34: h | E34: 4 | F34: 1 | G34: 17 | H34: =G34*E34*F34 -> 68 | K34: =((E34+E35)/2)/8 -> 0.5 | M34: =0.02*2*5*1.1 -> 0.22
C35: M.Ajudante | D35: h | E35: 4 | F35: 0 | G35: 12 | H35: =G35*E35*F35 -> 0
C36: Martelo demolidor 10kg aluguer | D36: dia | E36: 1 | F36: 1 | G36: 25 | H36: =G36*E36*F36 -> 25
C37: Broca martelo | D37: un | E37: 1 | F37: 1 | G37: 4 | H37: =G37*E37*F37 -> 4
C39: Vazadouro | D39: un | E39: =ROUNDUP((SUM(M34:M44)/300),0) -> 1 | F39: 1 | G39: =200*M34/6 -> 7.3333333 | H39: =G39*E39*F39 -> 7.3333333
C40: Transporte de lixo | D40: h | E40: 1 | F40: 1 | G40: 10 | H40: =G40*E40*F40 -> 10
C41: Transporte TKH | D41: un | E41: 1 | F41: 1 | G41: 20 | H41: =G41*E41*F41 -> 20
C42: Acessórios | D42: vg | E42: 1 | F42: 0 | G42: 10 | H42: =G42*E42*F42 -> 0
C43: Total | H43: =SUM(H34:H42) -> 134.33333
C44: Total/m2 | E44: Área | G44: 10 | H44: =ROUNDUP((H43/G44),0) -> 14
B46: ITEM | C46: DESCRIÇÃO | D46: UN | E46: QTD | G46: V.UN | H46: V.TOTAL | I46: Consumos /rendimentos | K46: Tempo em dias | L46: Vazadouro | N46: Ref. ITEM
...

Sheet Lista de custos obra
B2: ITEM | C2: DESCRIÇÃO | D2: UN | E2: Quantidade | F2: V.UN | G2: V.TOTAL | H2: Ref. ITEM
B4: MATERIAIS OBRA | G4: =F4*E4 -> 0
G5: =F5*E5 -> 0
G6: =F6*E6 -> 0
G7: =F7*E7 -> 0
G8: =F8*E8 -> 0
G9: =F9*E9 -> 0
G10: =F10*E10 -> 0
G11: =F11*E11 -> 0
G12: =F12*E12 -> 0
G13: =F13*E13 -> 0
G14: =F14*E14 -> 0
G15: =F15*E15 -> 0
G16: =F16*E16 -> 0
... G20: =F20*E20 -> 0
C21: Total | G21: =SUM(G4:G20) -> 0
B23: ITEM | C23: DESCRIÇÃO | D23: UN | E23: Quantidade | F23: V.UN | G23: V.TOTAL | H23: Ref. ITEM
B25: MÃO DE OBRA
C34: Total | G34: =SUM(G25:G33) -> 0
B36: ITEM | C36: DESCRIÇÃO | D36: UN | E36: Quantidade | F36: V.UN | G36: V.TOTAL | H36: Ref. ITEM
B38: DESLOCAÇÕES
C47: Total | G47: =SUM(G38:G46) -> 0
B49: Total | G49: =G21+G34+G47 -> 0

Sheet MQT Real - Analitico
B2: =MQT!B2 -> CO26/0034
B3: =MQT!B3 -> Cliente: Tiago Parada | J3: Analise financeira | P3: =MQT!P3 -> FI Estrutura | R3: =MQT!R3 -> Negociação | S3: =MQT!S3 -> Lucro | T3: =MQT!T3 -> Custo Fixo | U3: =MQT!U3 -> K médio
B4: =MQT!B4 -> Morada: Rua António José de Almeida, 3º Direito, Brandoa, 2650-381 | P4: =MQT!P4 -> 1.15 | R4: =MQT!R4 -> 1 | S4: =MQT!S4 -> 227.43 | T4: =MQT!T4 -> 227.43 | U4: =MQT!U4 -> 1.3
B5: =MQT!B5 -> Responsável: Vinícius Tomaz | P5: =MQT!P5 -> Margem - K
H6: MD05.00 | P6: =MQT!P6 -> Const. civil | Q6: =MQT!Q6 -> Águas | R6: =MQT!R6 -> Gás | S6: =MQT!S6 -> Eletricidade | T6: =MQT!T6 -> AVAC | U6: =MQT!U6 -> SCIE
A7: ITEM | B7: DESCRIÇÃO | C7: UN | D7: QTD | E7: VALOR UNITÁRIO CUSTO | F7: VALOR TOTAL CUSTO | G7: VALOR UNITÁRIO | H7: VALOR TOTAL | J7: Rentabilidade Estimada € | K7: Rentabilidade Estimada % | M7: COMENTÁRIOS | N7: Margem Cap. | P7: =MQT!P7 -> 1.15 | Q7: =MQT!Q7 -> 1.25 | R7: =MQT!R7 -> 1.25 | S7: =MQT!S7 -> 1.25 | T7: =MQT!T7 -> 1.25 | U7: =MQT!U7 -> 1.25
A8: 1 | B8: =MQT!B8 -> Quarto 01 - Crianças | F8: =('Lista de custos obra'!$G$49)*M8 -> #REF! | H8: =SUM(H9:H12) -> #REF! | J8: =SUM(J9:J12) -> #REF! | M8: =H8/$H$68 -> #REF! | N8: =$P$7*R4 -> 1.15
A9: 1.1 | B9: =MQT!B9 -> Solução para tetos interiores, constituída por estrutura com perfis metálicos horizontais F530 afastados a cada 500 mm, suspensos por elementos verticais fixados ao teto, nos quais é fixada 1 camada de placas Gyptec BA13A (STANDARD). Massas, bandas para juntas e acessórios de fixação. Superfícies prontas para acabamento final de pintura ou decoração | G9: =MQT!G9 -> 496.6 | H9: =MQT!H9 -> 496.6 | J9: =H9-F9 -> 496.6 | K9: =(H9/F9)-100% -> #DIV/0!
A10: 1.2 | B10: =MQT!B10 -> Execução de esquema de pintura em teto com Tinta Robbialac 2 em 1 branco, aplicado em 2 demão. Inclui proteção de rodapé, caixilharias, guarnições de portas, utilizando fita multisuperficies, e manga plástica para pavimento | G10: =MQT!G10 -> 278.85 | H10: =MQT!H10 -> 278.85 | J10: =H10-F10 -> 278.85 | K10: =(H10/F10)-100% -> #DIV/0!
A11: 1.3 | B11: =MQT!B11 -> Fornecimento de Sanca HOMESTAR A5 200X3.5X3.5cm em todo perimetro do teto falso. | G11: =MQT!G11 -> 211.523 | H11: =MQT!H11 -> 211.523 | J11: =H11-F11 -> 211.523 | K11: =(H11/F11)-100% -> #DIV/0!
A12: 1.4 | B12: =MQT!#REF! -> #REF! | G12: =MQT!#REF! -> #REF! | H12: =MQT!#REF! -> #REF! | J12: =H12-F12 -> #REF! | K12: =(H12/F12)-100% -> #REF!
A13: 2 | B13: =MQT!B12 -> 0 | F13: =('Lista de custos obra'!$G$49)*M13 -> #REF! | H13: =MQT!H12 -> 984.087 | J13: =SUM(J14:J17) -> 984.087 | M13: =H13/$H$68 -> #REF! | N13: =$P$7*R4 -> 1.15
A14: 2.1 | B14: =MQT!B13 -> Solução para tetos interiores, constituída por estrutura com perfis metálicos horizontais F530 afastados a cada 500 mm, suspensos por elementos verticais fixados ao teto, nos quais é fixada 1 camada de placas Gyptec BA13A (STANDARD). Massas, bandas para juntas e acessórios de fixação. Superfícies prontas para acabamento final de pintura ou decoração | G14: =MQT!G13 -> 496.6 | H14: =MQT!H13 -> 496.6 | J14: =H14-F14 -> 496.6 | K14: =(H14/F14)-100% -> #DIV/0!
A15: 2.2 | B15: =MQT!B14 -> Execução de esquema de pintura em teto com Tinta Robbialac 2 em 1 branco, aplicado em 2 demão. Inclui proteção de rodapé, caixilharias, guarnições de portas, utilizando fita multisuperficies, e manga plástica para pavimento | G15: =MQT!G14 -> 272.35 | H15: =MQT!H14 -> 272.35 | J15: =H15-F15 -> 272.35 | K15: =(H15/F15)-100% -> #DIV/0!
A16: 2.3 | B16: =MQT!B15 -> Fornecimento de Sanca HOMESTAR A5 200X3.5X3.5cm em todo perimetro do teto falso. | G16: =MQT!G15 -> 215.137 | H16: =MQT!H15 -> 215.137 | J16: =H16-F16 -> 215.137 | K16: =(H16/F16)-100% -> #DIV/0!
A17: 2.4 | B17: =MQT!B16 -> 0 | G17: =MQT!G16 -> 0 | H17: =MQT!H16 -> 0 | J17: =H17-F17 -> 0 | K17: =(H17/F17)-100% -> #DIV/0!
A18: 3 | B18: =MQT!B17 -> 0 | F18: =('Lista de custos obra'!$G$49)*M18 -> #REF! | H18: =MQT!H17 -> 0 | J18: =SUM(J19:J22) -> #REF! | M18: =H18/$H$68 -> #REF! | N18: =$P$7*R4 -> 1.15
A19: 3.1 | B19: =MQT!#REF! -> #REF! | G19: =MQT!#REF! -> #REF! | H19: =MQT!#REF! -> #REF! | J19: =H19-F19 -> #REF! | K19: =(H19/F19)-100% -> #REF!
A20: 3.2 | B20: =MQT!#REF! -> #REF! | G20: =MQT!#REF! -> #REF! | H20: =MQT!#REF! -> #REF! | J20: =H20-F20 -> #REF! | K20: =(H20/F20)-100% -> #REF!
A21: 3.3 | B21: =MQT!#REF! -> #REF! | G21: =MQT!#REF! -> #REF! | H21: =MQT!#REF! -> #REF! | J21: =H21-F21 -> #REF! | K21: =(H21/F21)-100% -> #REF!
A22: 3.4 | B22: =MQT!#REF! -> #REF! | G22: =MQT!#REF! -> #REF! | H22: =MQT!#REF! -> #REF! | J22: =H22-F22 -> #REF! | K22: =(H22/F22)-100% -> #REF!
A23: 4 | B23: =MQT!#REF! -> #REF! | F23: =('Lista de custos obra'!$G$49)*M23 -> #REF! | H23: =MQT!#REF! -> #REF! | J23: =SUM(J24:J27) -> #REF! | M23: =H23/$H$68 -> #REF! | N23: =$P$7*R4 -> 1.15
A24: 4.1 | B24: =MQT!#REF! -> #REF! | G24: =MQT!#REF! -> #REF! | H24: =MQT!#REF! -> #REF! | J24: =H24-F24 -> #REF! | K24: =(H24/F24)-100% -> #REF!
A25: 4.2 | B25: =MQT!#REF! -> #REF! | G25: =MQT!#REF! -> #REF! | H25: =MQT!#REF! -> #REF! | J25: =H25-F25 -> #REF! | K25: =(H25/F25)-100% -> #REF!
A26: 4.3 | B26: =MQT!#REF! -> #REF! | G26: =MQT!#REF! -> #REF! | H26: =MQT!#REF! -> #REF! | J26: =H26-F26 -> #REF! | K26: =(H26/F26)-100% -> #REF!
A27: 4.4 | B27: =MQT!#REF! -> #REF! | G27: =MQT!#REF! -> #REF! | H27: =MQT!#REF! -> #REF! | J27: =H27-F27 -> #REF! | K27: =(H27/F27)-100% -> #REF!
A28: 5 | B28: =MQT!#REF! -> #REF! | F28: =('Lista de custos obra'!$G$49)*M28 -> #REF! | H28: =MQT!#REF! -> #REF! | J28: =SUM(J29:J32) -> #REF! | M28: =H28/$H$68 -> #REF! | N28: =$P$7*R4 -> 1.15
A29: 5.1 | B29: =MQT!#REF! -> #REF! | G29: =MQT!#REF! -> #REF! | H29: =MQT!#REF! -> #REF! | J29: =H29-F29 -> #REF! | K29: =(H29/F29)-100% -> #REF!
A30: 5.2 | B30: =MQT!#REF! -> #REF! | G30: =MQT!#REF! -> #REF! | H30: =MQT!#REF! -> #REF! | J30: =H30-F30 -> #REF! | K30: =(H30/F30)-100% -> #REF!
A31: 5.3 | B31: =MQT!#REF! -> #REF! | G31: =MQT!#REF! -> #REF! | H31: =MQT!#REF! -> #REF! | J31: =H31-F31 -> #REF! | K31: =(H31/F31)-100% -> #REF!
A32: 5.4 | B32: =MQT!#REF! -> #REF! | G32: =MQT!#REF! -> #REF! | H32: =MQT!#REF! -> #REF! | J32: =H32-F32 -> #REF! | K32: =(H32/F32)-100% -> #REF!
A33: 6 | B33: =MQT!#REF! -> #REF! | F33: =('Lista de custos obra'!$G$49)*M33 -> #REF! | H33: =MQT!#REF! -> #REF! | J33: =SUM(J34:J37) -> #REF! | M33: =H33/$H$68 -> #REF! | N33: =$P$7*R4 -> 1.15
A34: 6.1 | B34: =MQT!#REF! -> #REF! | G34: =MQT!#REF! -> #REF! | H34: =MQT!#REF! -> #REF! | J34: =H34-F34 -> #REF! | K34: =(H34/F34)-100% -> #REF!
A35: 6.2 | B35: =MQT!#REF! -> #REF! | G35: =MQT!#REF! -> #REF! | H35: =MQT!#REF! -> #REF! | J35: =H35-F35 -> #REF! | K35: =(H35/F35)-100% -> #REF!
A36: 6.3 | B36: =MQT!#REF! -> #REF! | G36: =MQT!#REF! -> #REF! | H36: =MQT!#REF! -> #REF! | J36: =H36-F36 -> #REF! | K36: =(H36/F36)-100% -> #REF!
A37: 6.4 | B37: =MQT!#REF! -> #REF! | G37: =MQT!#REF! -> #REF! | H37: =MQT!#REF! -> #REF! | J37: =H37-F37 -> #REF! | K37: =(H37/F37)-100% -> #REF!
A38: 7 | B38: =MQT!#REF! -> #REF! | F38: =('Lista de custos obra'!$G$49)*M38 -> #REF! | H38: =MQT!#REF! -> #REF! | J38: =SUM(J39:J42) -> #REF! | M38: =H38/$H$68 -> #REF! | N38: =$P$7*R4 -> 1.15
A39: 7.1 | B39: =MQT!#REF! -> #REF! | G39: =MQT!#REF! -> #REF! | H39: =MQT!#REF! -> #REF! | J39: =H39-F39 -> #REF! | K39: =(H39/F39)-100% -> #REF!
A40: 7.2 | B40: =MQT!#REF! -> #REF! | G40: =MQT!#REF! -> #REF! | H40: =MQT!#REF! -> #REF! | J40: =H40-F40 -> #REF! | K40: =(H40/F40)-100% -> #REF!
A41: 7.3 | B41: =MQT!#REF! -> #REF! | G41: =MQT!#REF! -> #REF! | H41: =MQT!#REF! -> #REF! | J41: =H41-F41 -> #REF! | K41: =(H41/F41)-100% -> #REF!
...

Sheet Lista de composição de testes
B3: ITEM | C3: DESCRIÇÃO | D3: UN | E3: QTD | G3: V.UN | H3: V.TOTAL S/Margem | I3: V.TOTAL C/Margem 1,3
E4: Qtd padrão | F4: Qtd pontual
B5: Relatório Técnico | C5: Eng. Civil | D5: h | E5: 4 | F5: 1 | G5: 25 | H5: =G5*E5 -> 100 | I5: =G5*E5*1.6 -> 160
C6: Transporte | D6: un | E6: 1 | F6: 1 | G6: 20 | H6: =G6*E6 -> 20 | I6: =G6*E6*2 -> 40
C7: Acessórios
C8: Total | H8: =SUM(H5:H7) -> 120 | I8: =SUM(I5:I7) -> 200
C9: Total/m2 | E9: Área | G9: 1 | H9: =ROUNDUP((H8/G9),0) -> 120 | I9: =ROUNDUP((I8/G9),0) -> 200
B11: ITEM | C11: DESCRIÇÃO | D11: UN | E11: QTD | G11: V.UN | H11: V.TOTAL S/Margem | I11: V.TOTAL C/Margem
E12: Qtd padrão | F12: Qtd pontual
B13: Teste Corantes | C13: Técnico | D13: h | E13: 1 | F13: 1 | G13: 25 | H13: =G13*E13 -> 25 | I13: =G13*E13*1.3 -> 32.5
C14: Material | D14: un | E14: 1 | F14: 1 | G14: 5 | H14: =G14*E14 -> 5 | I14: =G14*E14*1.35 -> 6.75
C15: Acessórios
C16: Total | H16: =SUM(H13:H15) -> 30 | I16: =SUM(I13:I15) -> 39.25
C17: Total/m2 | E17: Área | G17: 1 | H17: =ROUNDUP((H16/G17),0) -> 30 | I17: =ROUNDUP((I16/G17),0) -> 40
B19: ITEM | C19: DESCRIÇÃO | D19: UN | E19: QTD | G19: V.UN | H19: V.TOTAL S/Margem | I19: V.TOTAL C/Margem
E20: Qtd padrão | F20: Qtd pontual
B21: Teste de pressão | C21: Técnico | D21: h | E21: 1 | F21: 1 | G21: 25 | H21: =G21*E21 -> 25 | I21: =G21*E21*1.3 -> 32.5
C22: Material | D22: un | E22: 1 | F22: 1 | G22: 5 | H22: =G22*E22 -> 5 | I22: =G22*E22*1.35 -> 6.75
C23: Acessórios
C24: Total | H24: =SUM(H21:H23) -> 30 | I24: =SUM(I21:I23) -> 39.25
C25: Total/m2 | E25: Área | G25: 1 | H25: =ROUNDUP((H24/G25),0) -> 30 | I25: =ROUNDUP((I24/G25),0) -> 40
B27: ITEM | C27: DESCRIÇÃO | D27: UN | E27: QTD | G27: V.UN | H27: V.TOTAL S/Margem | I27: V.TOTAL C/Margem
E28: Qtd padrão | F28: Qtd pontual
B29: Teste de obturação | C29: Técnico | D29: h | E29: 1 | F29: 1 | G29: 25 | H29: =G29*E29 -> 25 | I29: =G29*E29*1.3 -> 32.5
C30: Material | D30: un | E30: 1 | F30: 1 | G30: 5 | H30: =G30*E30 -> 5 | I30: =G30*E30*1.35 -> 6.75
C31: Acessórios
C32: Total | H32: =SUM(H29:H31) -> 30 | I32: =SUM(I29:I31) -> 39.25
C33: Total/m2 | E33: Área | G33: 1 | H33: =ROUNDUP((H32/G33),0) -> 30 | I33: =ROUNDUP((I32/G33),0) -> 40
B35: ITEM | C35: DESCRIÇÃO | D35: UN | E35: QTD | G35: V.UN | H35: V.TOTAL S/Margem | I35: V.TOTAL C/Margem
E36: Qtd padrão | F36: Qtd pontual
B37: Teste com termografia | C37: Técnico | D37: h | E37: 1 | F37: 1 | G37: 25 | H37: =G37*E37 -> 25 | I37: =G37*E37*1.3 -> 32.5
C38: Material | D38: un | E38: 1 | F38: 1 | G38: 5 | H38: =G38*E38 -> 5 | I38: =G38*E38*1.35 -> 6.75
C39: Acessórios
C40: Total | H40: =SUM(H37:H39) -> 30 | I40: =SUM(I37:I39) -> 39.25
C41: Total/m2 | E41: Área | G41: 1 | H41: =ROUNDUP((H40/G41),0) -> 30 | I41: =ROUNDUP((I40/G41),0) -> 40
B43: ITEM | C43: DESCRIÇÃO | D43: UN | E43: QTD | G43: V.UN | H43: V.TOTAL S/Margem | I43: V.TOTAL C/Margem
E44: Qtd padrão | F44: Qtd pontual
B45: Deslocação | C45: Deslocação | D45: un | E45: 1 | F45: 1 | G45: 25.015 | H45: =G45*E45 -> 25.015 | I45: =G45*E45*1.58 -> 39.5237
C46: Deslocação fora lisboa | D46: km | E46: 1 | F46: 1 | G46: 0.4 | H46: =G46*E46 -> 0.4 | I46: -
C47: Acessórios
...

Sheet Lista de composição TB pontuais
B2: ITEM | C2: DESCRIÇÃO | D2: UN | E2: QTD | F2: V.UN | G2: V.TOTAL | H2: K | I2: V.UN - Venda | J2: V.TOTAL - Venda | K2: IVA 23% | M2: Rentabilidade Estimada € | N2: Rentabilidade Estimada %
B4: Reparação de rotura em tubo multicamada Ø20mm, incluindo remoção de cerâmico, abertura de roço, fecho com argamassa de reboco, fornecimento e aplicação de cerâmica similar a existente, incluindo todos os trabalhos necessários para excelente acabamento. | C4: Canalização | G4: =SUM(G5:G12) -> 0
C5: Desmontagem (loiças) | D5: un | F5: 50 | G5: =F5*E5 -> 0 | H5: 1.45 | I5: =F5*$H$5 -> 72.5 | J5: =I5*E5 -> 0 | K5: =J5*1.23 -> 0 | M5: =J5-G5 -> 0 | N5: =(J5/G5)-100% -> #DIV/0!
C6: Remoção de cerâmicos | D6: m2 | F6: 15 | G6: =F6*E6 -> 0 | I6: =F6*$H$5 -> 21.75 | J6: =I6*E6 -> 0 | K6: =J6*1.23 -> 0 | M6: =J6-G6 -> 0 | N6: =(J6/G6)-100% -> #DIV/0!
C7: Abertura de roços | D7: m | F7: 28.5 | G7: =F7*E7 -> 0 | I7: =F7*$H$5 -> 41.325 | J7: =I7*E7 -> 0 | K7: =J7*1.23 -> 0 | M7: =J7-G7 -> 0 | N7: =(J7/G7)-100% -> #DIV/0!
C8: Fornecimento e aplicação de tubo multicamada 20mm | D8: m | F8: 38 | G8: =F8*E8 -> 0 | I8: =F8*$H$5 -> 55.1 | J8: =I8*E8 -> 0 | K8: =J8*1.23 -> 0 | M8: =J8-G8 -> 0 | N8: =(J8/G8)-100% -> #DIV/0!
C9: Oficial de Canalizador | D9: h | F9: 17 | G9: =F9*E9 -> 0 | I9: =F9*$H$5 -> 24.65 | J9: =I9*E9 -> 0 | K9: =J9*1.23 -> 0 | M9: =J9-G9 -> 0 | N9: =(J9/G9)-100% -> #DIV/0!
C10: Ajudante de predeiro | D10: h | F10: 12 | G10: =F10*E10 -> 0 | I10: =F10*$H$5 -> 17.4 | J10: =I10*E10 -> 0 | K10: =J10*1.23 -> 0 | M10: =J10-G10 -> 0 | N10: =(J10/G10)-100% -> #DIV/0!
C11: Depósito de resíduos a vazadouro | D11: un | F11: 20 | G11: =F11*E11 -> 0 | I11: =F11*$H$5 -> 29 | J11: =I11*E11 -> 0 | K11: =J11*1.23 -> 0 | M11: =J11-G11 -> 0 | N11: =(J11/G11)-100% -> #DIV/0!
C12: Deslocação | D12: un | F12: 20 | G12: =F12*E12 -> 0 | I12: =F12*$H$5 -> 29 | J12: =I12*E12 -> 0 | K12: =J12*1.23 -> 0 | M12: =J12-G12 -> 0 | N12: =(J12/G12)-100% -> #DIV/0!
C13: Construção civil | G13: =SUM(G14:G24) -> 0
C14: Oficial Pedreiro | D14: h | F14: 17 | G14: =F14*E14 -> 0 | I14: =F14*$H$5 -> 24.65 | J14: =I14*E14 -> 0 | K14: =J14*1.23 -> 0 | M14: =J14-G14 -> 0 | N14: =(J14/G14)-100% -> #DIV/0!
C15: Ajudante de pedreiro | D15: h | F15: 12 | G15: =F15*E15 -> 0 | I15: =F15*$H$5 -> 17.4 | J15: =I15*E15 -> 0 | K15: =J15*1.23 -> 0 | M15: =J15-G15 -> 0 | N15: =(J15/G15)-100% -> #DIV/0!
C16: Fecho de roços com argamassa | D16: m | F16: 28.5 | G16: =F16*E16 -> 0 | I16: =F16*$H$5 -> 41.325 | J16: =I16*E16 -> 0 | K16: =J16*1.23 -> 0 | M16: =J16-G16 -> 0 | N16: =(J16/G16)-100% -> #DIV/0!
C17: Regularização de paredes | D17: m2 | F17: 12 | G17: =F17*E17 -> 0 | I17: =F17*$H$5 -> 17.4 | J17: =I17*E17 -> 0 | K17: =J17*1.23 -> 0 | M17: =J17-G17 -> 0 | N17: =(J17/G17)-100% -> #DIV/0!
C18: Fornecimento e aplicação de cerâmico | D18: m2 | F18: 40 | G18: =F18*E18 -> 0 | I18: =F18*$H$5 -> 58 | J18: =I18*E18 -> 0 | K18: =J18*1.23 -> 0 | M18: =J18-G18 -> 0 | N18: =(J18/G18)-100% -> #DIV/0!
C19: Montagem (loiças) | D19: un | F19: 50 | G19: =F19*E19 -> 0 | I19: =F19*$H$5 -> 72.5 | J19: =I19*E19 -> 0 | K19: =J19*1.23 -> 0 | M19: =J19-G19 -> 0 | N19: =(J19/G19)-100% -> #DIV/0!
C20: Trabalhos de movimentação e proteção de móveis | D20: h | F20: 12 | G20: =F20*E20 -> 0 | I20: =F20*$H$5 -> 17.4 | J20: =I20*E20 -> 0 | K20: =J20*1.23 -> 0 | M20: =J20-G20 -> 0 | N20: =(J20/G20)-100% -> #DIV/0!
C21: Trabalhos preparatórios de obra | D21: h | F21: 12 | G21: =F21*E21 -> 0 | I21: =F21*$H$5 -> 17.4 | J21: =I21*E21 -> 0 | K21: =J21*1.23 -> 0 | M21: =J21-G21 -> 0 | N21: =(J21/G21)-100% -> #DIV/0!
C22: Depósito de resíduos a vazadouro | D22: un | F22: 20 | G22: =F22*E22 -> 0 | I22: =F22*$H$5 -> 29 | J22: =I22*E22 -> 0 | K22: =J22*1.23 -> 0 | M22: =J22-G22 -> 0 | N22: =(J22/G22)-100% -> #DIV/0!
C23: Limpeza de obra | D23: un | F23: 20 | G23: =F23*E23 -> 0 | I23: =F23*$H$5 -> 29 | J23: =I23*E23 -> 0 | K23: =J23*1.23 -> 0 | M23: =J23-G23 -> 0 | N23: =(J23/G23)-100% -> #DIV/0!
C24: Deslocação | D24: un | F24: 20 | G24: =F24*E24 -> 0 | I24: =F24*$H$5 -> 29 | J24: =I24*E24 -> 0 | K24: =J24*1.23 -> 0 | M24: =J24-G24 -> 0 | N24: =(J24/G24)-100% -> #DIV/0!
C25: Total | G25: =SUM(G5:G12,G14:G24) -> 0 | I25: Total | J25: =SUM(J5:J24) -> 0 | K25: =SUM(K5:K24) -> 0 | M25: =SUM(M5:M24) -> 0
C26: Total/vg | E26: valor global | F26: 1 | G26: =ROUNDUP((G25/F26),0) -> 0
B28: ITEM | C28: DESCRIÇÃO | D28: UN | E28: QTD | F28: V.UN | G28: V.TOTAL | H28: K | I28: V.UN - Venda | J28: V.TOTAL - Venda | K28: IVA 23% | M28: Rentabilidade Estimada € | N28: Rentabilidade Estimada %
B30: Reparação de rotura em tubo multicamada Ø20mm, incluindo abertura de roço, fecho com argamassa de reboco, preparação de superficie com massa de estuque, execução de pintura com primário e tinta plástica, incluindo todos os trabalhos necessários para excelente acabamento. | C30: Canalização | G30: =SUM(G31:G36) -> 0
C31: Abertura de roços | D31: m | F31: 28.5 | G31: =F31*E31 -> 0 | H31: 1.45 | I31: =F31*$H$31 -> 41.325 | J31: =I31*E31 -> 0 | K31: =J31*1.23 -> 0 | M31: =J31-G31 -> 0 | N31: =(J31/G31)-100% -> #DIV/0!
C32: Fornecimento e aplicação de tubo multicamada 20mm | D32: m | F32: 38 | G32: =F32*E32 -> 0 | I32: =F32*$H$31 -> 55.1 | J32: =I32*E32 -> 0 | K32: =J32*1.23 -> 0 | M32: =J32-G32 -> 0 | N32: =(J32/G32)-100% -> #DIV/0!
C33: Oficial de Canalizador | D33: h | F33: 17 | G33: =F33*E33 -> 0 | I33: =F33*$H$31 -> 24.65 | J33: =I33*E33 -> 0 | K33: =J33*1.23 -> 0 | M33: =J33-G33 -> 0 | N33: =(J33/G33)-100% -> #DIV/0!
C34: Ajudante de canalizador | D34: h | F34: 12 | G34: =F34*E34 -> 0 | I34: =F34*$H$31 -> 17.4 | J34: =I34*E34 -> 0 | K34: =J34*1.23 -> 0 | M34: =J34-G34 -> 0 | N34: =(J34/G34)-100% -> #DIV/0!
C35: Depósito de resíduos a vazadouro | D35: un | F35: 20 | G35: =F35*E35 -> 0 | I35: =F35*$H$31 -> 29 | J35: =I35*E35 -> 0 | K35: =J35*1.23 -> 0 | M35: =J35-G35 -> 0 | N35: =(J35/G35)-100% -> #DIV/0!
C36: Deslocação | D36: un | F36: 20 | G36: =F36*E36 -> 0 | I36: =F36*$H$31 -> 29 | J36: =I36*E36 -> 0 | K36: =J36*1.23 -> 0 | M36: =J36-G36 -> 0 | N36: =(J36/G36)-100% -> #DIV/0!
C37: Construção civil | G37: =SUM(G38:G50) -> 0
C38: Oficial Pedreiro | D38: h | F38: 17 | G38: =F38*E38 -> 0 | I38: =F38*$H$31 -> 24.65 | J38: =I38*E38 -> 0 | K38: =J38*1.23 -> 0 | M38: =J38-G38 -> 0 | N38: =(J38/G38)-100% -> #DIV/0!
C39: Ajudante de pedreiro | D39: h | F39: 12 | G39: =F39*E39 -> 0 | I39: =F39*$H$31 -> 17.4 | J39: =I39*E39 -> 0 | K39: =J39*1.23 -> 0 | M39: =J39-G39 -> 0 | N39: =(J39/G39)-100% -> #DIV/0!
C40: Fecho de roços com argamassa | D40: m | F40: 28.5 | G40: =F40*E40 -> 0 | I40: =F40*$H$31 -> 41.325 | J40: =I40*E40 -> 0 | K40: =J40*1.23 -> 0 | M40: =J40-G40 -> 0 | N40: =(J40/G40)-100% -> #DIV/0!
C41: Execução de reboco para estuque | D41: m2 | F41: 13 | G41: =F41*E41 -> 0 | I41: =F41*$H$31 -> 18.85 | J41: =I41*E41 -> 0 | K41: =J41*1.23 -> 0 | M41: =J41-G41 -> 0 | N41: =(J41/G41)-100% -> #DIV/0!
C42: Execução de estuque em paredes | D42: m2 | F42: 15 | G42: =F42*E42 -> 0 | I42: =F42*$H$31 -> 21.75 | J42: =I42*E42 -> 0 | K42: =J42*1.23 -> 0 | M42: =J42-G42 -> 0 | N42: =(J42/G42)-100% -> #DIV/0!
C43: Preparação de superficies (lixar/emassar) | D43: m2 | F43: 10 | G43: =F43*E43 -> 0 | I43: =F43*$H$31 -> 14.5 | J43: =I43*E43 -> 0 | K43: =J43*1.23 -> 0 | M43: =J43-G43 -> 0 | N43: =(J43/G43)-100% -> #DIV/0!
C44: Fornecimento e aplicação de primário | D44: m2 | F44: 6 | G44: =F44*E44 -> 0 | I44: =F44*$H$31 -> 8.7 | J44: =I44*E44 -> 0 | K44: =J44*1.23 -> 0 | M44: =J44-G44 -> 0 | N44: =(J44/G44)-100% -> #DIV/0!
...
